An error occurred while executing the following cell:
------------------
fixed_vars = [None, 1]

for fixed_var in fixed_vars:
    model = DensityNetwork([1, 50, 50], [20, 1], fixed_var)

    def negloglik(y, rv_y):
        return -rv_y.log_prob(y)

    model.compile(optimizer=tf.optimizers.Adam(learning_rate=0.01), loss=negloglik)
    history = model.fit(x, y, epochs=500, batch_size=100, verbose=False)
    if fixed_var is not None:
        # estimate MLE of sigma
        yhat_train = model(x)
        ypred = yhat_train.mean().numpy()[:, 0]
        # print(ypred.shape)
        residuals = y - ypred
        mse = np.mean((residuals**2))
        # mse = scipy.stats.trim_mean(residuals ** 2, proportiontocut=0.1)
        model.fixed_variance = mse
        # print(model.fixed_variance)
    yhat = model(x_tst)  # a Gaussian distribution object

    plt.plot(history.history["loss"], label="Train")
    plt.legend()
    plt.xlabel("Epoch")
    plt.ylabel("NLL")
    plt.show()

    plt.figure()
    plt.plot(x, y, "b.", label="observed")
    m = yhat.mean()
    s = yhat.stddev()
    plt.plot(x_tst, m, "r", linewidth=4, label="mean")
    plt.plot(x_tst, m + 2 * s, "g", linewidth=2, label=r"mean + 2 stddev")
    plt.plot(x_tst, m - 2 * s, "g", linewidth=2, label=r"mean - 2 stddev")
    # plt.ylim([-10,10])
    plt.show()
------------------

---------------------------------------------------------------------------
AttributeError                            Traceback (most recent call last)
/tmp/ipykernel_4788/2370705851.py in <module>
      8 
      9     model.compile(optimizer=tf.optimizers.Adam(learning_rate=0.01), loss=negloglik)
---> 10     history = model.fit(x, y, epochs=500, batch_size=100, verbose=False)
     11     if fixed_var is not None:
     12         # estimate MLE of sigma

~/miniconda3/envs/py37/lib/python3.7/site-packages/keras/utils/traceback_utils.py in error_handler(*args, **kwargs)
     65     except Exception as e:  # pylint: disable=broad-except
     66       filtered_tb = _process_traceback_frames(e.__traceback__)
---> 67       raise e.with_traceback(filtered_tb) from None
     68     finally:
     69       del filtered_tb

~/miniconda3/envs/py37/lib/python3.7/site-packages/tensorflow/python/framework/func_graph.py in autograph_handler(*args, **kwargs)
   1145           except Exception as e:  # pylint:disable=broad-except
   1146             if hasattr(e, "ag_error_metadata"):
-> 1147               raise e.ag_error_metadata.to_exception(e)
   1148             else:
   1149               raise

AttributeError: in user code:

    File "/github/home/miniconda3/envs/py37/lib/python3.7/site-packages/keras/engine/training.py", line 1021, in train_function  *
        return step_function(self, iterator)
    File "/github/home/miniconda3/envs/py37/lib/python3.7/site-packages/keras/engine/training.py", line 1010, in step_function  **
        outputs = model.distribute_strategy.run(run_step, args=(data,))
    File "/github/home/miniconda3/envs/py37/lib/python3.7/site-packages/keras/engine/training.py", line 1000, in run_step  **
        outputs = model.train_step(data)
    File "/github/home/miniconda3/envs/py37/lib/python3.7/site-packages/keras/engine/training.py", line 860, in train_step
        loss = self.compute_loss(x, y, y_pred, sample_weight)
    File "/github/home/miniconda3/envs/py37/lib/python3.7/site-packages/keras/engine/training.py", line 919, in compute_loss
        y, y_pred, sample_weight, regularization_losses=self.losses)
    File "/github/home/miniconda3/envs/py37/lib/python3.7/site-packages/keras/engine/compile_utils.py", line 199, in __call__
        y_t, y_p, sw = match_dtype_and_rank(y_t, y_p, sw)
    File "/github/home/miniconda3/envs/py37/lib/python3.7/site-packages/keras/engine/compile_utils.py", line 675, in match_dtype_and_rank
        if y_t.shape.rank == 1 and y_p.shape.rank == 2:

    AttributeError: 'Normal' object has no attribute 'shape'

AttributeError: in user code:

    File "/github/home/miniconda3/envs/py37/lib/python3.7/site-packages/keras/engine/training.py", line 1021, in train_function  *
        return step_function(self, iterator)
    File "/github/home/miniconda3/envs/py37/lib/python3.7/site-packages/keras/engine/training.py", line 1010, in step_function  **
        outputs = model.distribute_strategy.run(run_step, args=(data,))
    File "/github/home/miniconda3/envs/py37/lib/python3.7/site-packages/keras/engine/training.py", line 1000, in run_step  **
        outputs = model.train_step(data)
    File "/github/home/miniconda3/envs/py37/lib/python3.7/site-packages/keras/engine/training.py", line 860, in train_step
        loss = self.compute_loss(x, y, y_pred, sample_weight)
    File "/github/home/miniconda3/envs/py37/lib/python3.7/site-packages/keras/engine/training.py", line 919, in compute_loss
        y, y_pred, sample_weight, regularization_losses=self.losses)
    File "/github/home/miniconda3/envs/py37/lib/python3.7/site-packages/keras/engine/compile_utils.py", line 199, in __call__
        y_t, y_p, sw = match_dtype_and_rank(y_t, y_p, sw)
    File "/github/home/miniconda3/envs/py37/lib/python3.7/site-packages/keras/engine/compile_utils.py", line 675, in match_dtype_and_rank
        if y_t.shape.rank == 1 and y_p.shape.rank == 2:

    AttributeError: 'Normal' object has no attribute 'shape'

